<mujoco model="hand model">
	<compiler angle="radian" autolimits="true" meshdir="./meshes" texturedir="assets" />
	<option integrator="implicit" />
	<default>
		<default class="zf">
			<geom type="mesh" contype="3" conaffinity="2" group="0" friction="0.7" solref="0.015 1" solimp="0.95 0.99 0.003" rgba="0.78 0.64 0.57 1" />
		</default>
		<default class="dau">
			<geom type="mesh" contype="3" conaffinity="2" group="0" friction="0.7" solref="0.015 1" solimp="0.95 0.99 0.003" rgba="0.78 0.64 0.37 1" />
		</default>
		<default class="base">
			<geom type="mesh" contype="3" conaffinity="2" group="0" friction="0.7" solref="0.015 1" solimp="0.95 0.99 0.003" rgba="0.74 0.60 0.47 0.3" />
		</default>
		<default class="other">
			<geom type="mesh" contype="3" conaffinity="2" group="0" friction="0.7" solref="0.015 1" solimp="0.95 0.99 0.003" rgba="0.74 0.60 0.67 0.3" />
		</default>
		<default class="visual">
			<geom type="mesh" contype="0" conaffinity="0" group="2" material="bone" rgba="0.68 0.64 0.57 1.0" />
		</default>
		<default class="tracker">
			<geom type="mesh" contype="0" conaffinity="0" group="2" rgba="0.2 0.2 1 0.2" />
		</default>
	</default>
	<asset>
		<mesh file="Segmentation_ZF_DIP.stl" name="ZF-DIP" scale="0.001 0.001 0.001" />
		<mesh file="Segmentation_ZF_PIP.stl" name="ZF-PIP1" scale="0.001 0.001 0.001" />
		<mesh file="zf_mid2.stl" name="ZF-PIP2" scale="0.001 0.001 0.001" />
		<mesh file="zf_mcp.stl" name="ZF-MCP" scale="0.001 0.001 0.001" />
		<mesh file="Segmentation_DAU_Osmetacarpale_1.stl" name="DAU-MCP" scale="0.001 0.001 0.001" />
		<mesh file="Segmentation_DAU_Phalax_proximalis.stl" name="DAU-PIP" scale="0.001 0.001 0.001" />
		<mesh file="Segmentation_DAU_DIP.stl" name="DAU-DIP" scale="0.001 0.001 0.001" />
		<mesh file="backhand.stl" name="BASE" scale="0.001 0.001 0.001" />
		<mesh file="rest.stl" name="OTHER" scale="0.001 0.001 0.001" />
		<texture type="skybox" builtin="gradient" rgb1="0.3 0.5 0.7" rgb2="0 0 0" width="512" height="3072" />
		<texture type="2d" name="groundplane" builtin="checker" mark="edge" rgb1="1 1 1" rgb2="1 1 1" markrgb="0.8 0.8 0.8" width="300" height="300" />
		<material name="groundplane" texture="groundplane" texuniform="true" texrepeat="10 10" reflectance="0.3" />
		<material name="bone" reflectance="1" shininess="0" specular="0" rgba="0.68 0.64 0.57 1" />
	</asset>
	<worldbody>
		<body name="ZF_MCP" pos="0.1765304360741342 -0.006212724687087806 0.36246523321202795" quat="0.9493391655149379 0.2596204789151585 0.14900580594456567 -0.09565367500559206">
			<geom class="zf" mesh="ZF-MCP" type="mesh" />
			<geom class="base" mesh="BASE" type="mesh" />
			<geom class="other" mesh="OTHER" type="mesh" />
			<body name="DAU_MCP" pos="-0.0051996219024619565 -0.017297986154240306 0.012909056180496493" quat="0.9963707275955191 0.024422273740191274 0.04402933783707002 0.06863193969111356">
				<geom class="dau" mesh="DAU-MCP" type="mesh" />
				<joint armature="0.001" axis="0.40901004102379035 0.7919085320270741 -0.4534221688938945" limited="true" name="ZF_MCP_to_DAU_CMC" pos="0.05845392354053609 -0.1978745892757368 -0.21942211755720506" range="-1.5 1" type="hinge" />
				<joint armature="0.001" axis="0.4967753211376007 -0.7419451851751502 -0.45025728478731575" limited="true" name="DAU_CMC_to_DAU_MCP" pos="0.052724838369525476 -0.19935575512856935 -0.22408553449262406" range="-0.2 1" type="hinge" />
				<geom class="visual" fromto="0.04805550124843744 -0.19238199446143817 -0.21985343405518026 0.0573941754906135 -0.20632951579570052 -0.22831763493006785" name="DAU_CMC_to_DAU_MCP_wrap" rgba=".2 .2 .5 0.4" size="0.005639576189568419" type="cylinder" density="0" contype="0" conaffinity="0" />
				<body name="DAU_PIP" pos="-0.004148970988564202 0.001735805600735077 -0.004146285024367472" quat="0.9982758293388541 0.009285212244582869 -0.04837647336581254 -0.03191974649152252">
					<geom class="dau" mesh="DAU-PIP" type="mesh" />
					<joint armature="0.001" axis="0.4006067326531987 -0.8774106652423261 -0.2639408461605503" limited="true" name="DAU_MCP_to_DAU_PIP" pos="0.0727821255956078 -0.20351842063086995 -0.1853582338288163" range="-0.2 1" type="hinge" />
					<geom class="visual" fromto="0.06986512094763302 -0.19712958394871122 -0.1834363573043216 0.0756991302435826 -0.2099072573130287 -0.18728011035331105" name="DAU_MCP_to_DAU_PIP_wrap" rgba=".2 .2 .5 0.4" size="0.004368880116400853" type="cylinder" density="0" contype="0" conaffinity="0" />
					<body name="DAU_DIP" pos="-0.00433924131526193 -0.0003637396778127311 -0.0020970245100165245" quat="0.9744341224117706 0.06503579821584744 -0.18094432561059517 -0.11622236041036497">
						<geom class="dau" mesh="DAU-DIP" type="mesh" />
						<joint armature="0.001" axis="0.31367467587006415 -0.8580231765623447 -0.40669942980003426" limited="true" name="DAU_PIP_to_DAU_DIP" pos="0.0796331707328216 -0.21237495949690408 -0.15234864770253553" range="-0.2 1" type="hinge" />
						<geom class="visual" fromto="0.07790014026037166 -0.2076344419306508 -0.15010166202217595 0.08136620120527151 -0.21711547706315734 -0.15459563338289517" name="DAU_PIP_to_DAU_DIP_wrap" rgba=".2 .2 .5 0.4" size="0.003314957704461596" type="cylinder" density="0" contype="0" conaffinity="0" />
						<body name="DAU_TIP" />
						<site name="FPL-1" pos="0.07617986335228798 -0.2164349065612825 -0.14549392680675224" type="sphere" size="0.0005" />
						<site name="EPL-1" pos="0.08278454435532315 -0.2128481996245333 -0.1451938607295752" type="sphere" size="0.0005" />
						<site name="thumb_tip" pos="0.082587 -0.22134 -0.128934" type="sphere" size="0.0005" />
					</body>
					<site name="EPL-2" pos="0.08224218866195501 -0.20837251280284236 -0.1535216694360387" type="sphere" size="0.0005" />
					<site name="EPL-3" pos="0.07222064685788276 -0.1999198568883619 -0.17396908771381936" type="sphere" size="0.0005" />
					<site name="EPB-1" pos="0.07847651865637922 -0.20413769959702835 -0.17347872119119845" type="sphere" size="0.0005" />
					<site name="FPL-2" pos="0.0760290359377246 -0.21216055303307393 -0.15563567738304457" type="sphere" size="0.0005" />
					<site name="FPL-3" pos="0.07029319124008324 -0.20946988827796797 -0.17189978841948889" type="sphere" size="0.0005" />
				</body>
				<site name="EPB-2" pos="0.07592438175162022 -0.20122150199685507 -0.1850281625625945" type="sphere" size="0.0005" />
				<site name="EPB-3" pos="0.060477917702416506 -0.19374199844932818 -0.21688536585851254" type="sphere" size="0.0005" />
				<site name="FPL-4" pos="0.06711087146248366 -0.20587478164234602 -0.18830641725242808" type="sphere" size="0.0005" />
				<site name="APL-1" pos="0.06271704076437273 -0.1977000442553416 -0.22016046175468032" type="sphere" size="0.0005" />
			</body>
			<body name="ZF_PIP2" pos="-0.04408808485454151 0.029136911946269977 -0.06062695362072164" quat="0.9849495052526392 -0.11495860271314842 -0.12714793269015798 0.02218997470572589">
				<geom class="zf" mesh="ZF-PIP2" type="mesh" />
				<joint armature="0.001" axis="0.8578015621998283 0.5139723785802518 -0.0029789165972422815" limited="true" name="ZF_MCP_to_ZF_PIP2" pos="0.042434736408437625 -0.17430024141801112 -0.16782877206684857" range="-0.4 1" type="hinge" />
				<geom class="visual" fromto="0.03721072156014954 -0.17743033520150522 -0.16781063045319158 0.04765875125672573 -0.1711701476345171 -0.16784691368050558" name="ZF_MCP_to_ZF_PIP2_wrap" rgba=".2 .2 .5 0.4" size="0.00365400233235141" type="cylinder" density="0" contype="0" conaffinity="0" />
				<body name="ZF_PIP1" pos="0.03674525175643409 -0.10101967260373558 0.09061853552879026" quat="0.9541882720651348 0.2689936670135175 0.12690393235707081 0.03259663345018418">
					<geom class="zf" mesh="ZF-PIP1" type="mesh" />
					<joint armature="0.001" axis="0.8575623725180784 0.5138829572014336 0.02260715681094902" limited="true" name="ZF_PIP2_to_ZF_PIP1" pos="0.05456171314997495 -0.19423572543588488 -0.12941855504857017" range="-0.4 1" type="hinge" />
					<geom class="visual" fromto="0.0506137946198933 -0.19660146361895323 -0.12952263052593088 0.058509631680056615 -0.1918699872528165 -0.12931447957120945" name="ZF_PIP2_to_ZF_PIP1_wrap" rgba=".2 .2 .5 0.4" size="0.002762191059168775" type="cylinder" density="0" contype="0" conaffinity="0" />
					<body name="ZF_DIP" pos="-0.006489833313809016 -0.016887511265440566 0.023041259917669664" quat="0.9983028291442446 0.052609884024385385 0.010451067252851741 0.022681195268635695">
						<geom class="zf" mesh="ZF-DIP" type="mesh" />
						<joint armature="0.001" axis="0.8680880701948858 0.41376338008343677 0.27426805808779137" limited="true" name="ZF_PIP1_to_ZF_DIP" pos="0.06197243447298718 -0.2138604192329433 -0.1201704459261653" range="-0.4 1" type="hinge" />
						<geom class="visual" fromto="0.058159880640969115 -0.21567762559074027 -0.12137500312694333 0.06578498830500523 -0.21204321287514633 -0.11896588872538726" name="ZF_PIP1_to_ZF_DIP_wrap" rgba=".2 .2 .5 0.4" size="0.0026351385046649513" type="cylinder" density="0" contype="0" conaffinity="0" />
						<body name="ZF_TIP" />
						<site name="ED-1" pos="0.06345094768734885 -0.218327969948429 -0.11391111976488638" type="sphere" size="0.0005" />
						<site name="FDP-1" pos="0.06432809657963354 -0.21958941627941314 -0.12052502992735097" type="sphere" size="0.0005" />
						<site name="index_tip" pos="0.06695 -0.230160 -0.111035" type="sphere" size="0.0005" />
					</body>
					<site name="ED-2" pos="0.06038826107850061 -0.21250561966377626 -0.11736054732022588" type="sphere" size="0.0005" />
					<site name="ED-3" pos="0.05471142759653134 -0.19707721985011575 -0.12131885210865372" type="sphere" size="0.0005" />
					<site name="FDP-2" pos="0.061807446257681316 -0.21267466607793398 -0.12254198149482397" type="sphere" size="0.0005" />
					<site name="FDP-3" pos="0.05761489709455216 -0.2020984636701569 -0.1270854409206569" type="sphere" size="0.0005" />
					<site name="EI-1" pos="0.05573732126240647 -0.1973502605018254 -0.12135900273168795" type="sphere" size="0.0005" />
					<site name="FDS-1" pos="0.05787033711811481 -0.2039381208446886 -0.12468581669061948" type="sphere" size="0.0005" />
				</body>
				<site name="ED-4" pos="0.05244191360473633 -0.190090072631836 -0.1292928497314453" type="sphere" size="0.0005" />
				<site name="ED-5" pos="0.0443320541381836 -0.1725892333984375 -0.15278924865722657" type="sphere" size="0.0005" />
				<site name="EI-2" pos="0.05301815032958984 -0.19127139282226563 -0.12737398834228517" type="sphere" size="0.0005" />
				<site name="EI-3" pos="0.04377632522583008 -0.17302584838867188 -0.1525018341064453" type="sphere" size="0.0005" />
				<site name="FDS-2" pos="0.053851776123046875 -0.1911654510498047 -0.13596832580566406" type="sphere" size="0.0005" />
				<site name="FDP-4" pos="0.05540545654296875 -0.19265214538574219 -0.13388643188476562" type="sphere" size="0.0005" />
				<site name="FDP-5" pos="0.046552120208740236 -0.18246701049804687 -0.15747040100097656" type="sphere" size="0.0005" />
				<site name="FDS-3" pos="0.048047260284423826 -0.1837753448486328 -0.15370108337402344" type="sphere" size="0.0005" />
			</body>
			<site name="ED-6" pos="0.04068317413330078 -0.1683495330810547 -0.16356614990234375" type="sphere" size="0.0005" />
			<site name="ED-7" pos="0.02870635032653809 -0.1841443328857422 -0.21635090942382812" type="sphere" size="0.0005" />
			<site name="ED-8" pos="0.032556884765625 -0.21127896118164066 -0.2505441009521484" type="sphere" size="0.0005" />
			<site name="EI-4" pos="0.0404731674194336 -0.16725772094726565 -0.16589578552246095" type="sphere" size="0.0005" />
			<site name="EI-5" pos="0.028191236495971682 -0.1843002166748047 -0.2169537841796875" type="sphere" size="0.0005" />
			<site name="EI-6" pos="0.03293711471557617 -0.21202293395996097 -0.24852492065429688" type="sphere" size="0.0005" />
			<site name="FDS-4" pos="0.04311767196655274 -0.1799432830810547 -0.17614850158691406" type="sphere" size="0.0005" />
			<site name="FDP-6" pos="0.04354349517822266 -0.17979544067382813 -0.1719917785644531" type="sphere" size="0.0005" />
			<site name="FDP-7" pos="0.0329781494140625 -0.20735281372070313 -0.22346496887207032" type="sphere" size="0.0005" />
			<site name="FDP-8" pos="0.03201940536499023 -0.21800865173339845 -0.24317700500488282" type="sphere" size="0.0005" />
			<site name="EPB-4" pos="0.03757329177856445 -0.20120518493652345 -0.24805575866699217" type="sphere" size="0.0005" />
			<site name="EPL-4" pos="0.041398563385009766 -0.18813050842285156 -0.2281511871337891" type="sphere" size="0.0005" />
			<site name="EPL-5" pos="0.04651138687133789 -0.20301907348632814 -0.24295352478027343" type="sphere" size="0.0005" />
			<site name="APL-2" pos="0.0483392333984375 -0.20248985290527344 -0.24085289306640625" type="sphere" size="0.0005" />
			<site name="FPL-5" pos="0.040508323669433605 -0.20416598510742187 -0.22414621276855468" type="sphere" size="0.0005" />
			<site name="FPL-6" pos="0.04095455169677734 -0.21076040649414066 -0.2438369171142578" type="sphere" size="0.0005" />
			<site name="FDS-5" pos="0.039476860046386716 -0.19787861633300782 -0.21464696044921874" type="sphere" size="0.0005" />
			<body name="slider-EI" pos="0.03293711471557617 -0.21202293395996097 -0.26852492065429688">
				<geom type="box" size="0.001 0.001 0.01" rgba="0 0 1 0" />
				<joint type="slide" axis="0 0 1" name="EI_slide" />
				<site name="EI-7" pos="0 0 0.01" type="sphere" size="0.0005" />
			</body>
			<body name="slider-FDP" pos="0.03201940536499023 -0.21800865173339845 -0.26317700500488282">
				<geom type="box" size="0.001 0.001 0.01" rgba="0 0 1 0" />
				<joint type="slide" axis="0 0 1" name="FDP_slide" />
				<site name="FDP-9" pos="0 0 0.01" type="sphere" size="0.0005" />
			</body>
			<body name="slider-EPB" pos="0.03757329177856445 -0.20120518493652345 -0.26805575866699217">
				<geom type="box" size="0.001 0.001 0.01" rgba="0 0 1 0" />
				<joint type="slide" axis="0 0 1" name="EPB_slide" />
				<site name="EPB-5" pos="0 0 0.01" type="sphere" size="0.0005" />
			</body>
			<body name="slider-ED" pos="0.032556884765625 -0.21127896118164066 -0.2705441009521484">
				<geom type="box" size="0.001 0.001 0.01" rgba="0 0 1 0" />
				<joint type="slide" axis="0 0 1" name="ED_slide" />
				<site name="ED-9" pos="0 0 0.01" type="sphere" size="0.0005" />
			</body>
			<body name="slider-FDS" pos="0.039476860046386716 -0.19787861633300782 -0.23464696044921874">
				<geom type="box" size="0.001 0.001 0.01" rgba="0 0 1 0" />
				<joint type="slide" axis="0 0 1" name="FDS_slide" />
				<site name="FDS-6" pos="0 0 0.01" type="sphere" size="0.0005" />
			</body>
			<body name="slider-EPL" pos="00.04651138687133789 -0.20301907348632814 -0.26295352478027343">
				<geom type="box" size="0.001 0.001 0.01" rgba="0 0 1 0" />
				<joint type="slide" axis="0 0 1" name="EPL_slide" />
				<site name="EPL-6" pos="0 0 0.01" type="sphere" size="0.0005" />
			</body>
			<body name="slider-FPL" pos="0.04095455169677734 -0.21076040649414066 -0.2638369171142578">
				<geom type="box" size="0.001 0.001 0.01" rgba="0 0 1 0" />
				<joint type="slide" axis="0 0 1" name="FPL_slide" />
				<site name="FPL-7" pos="0 0 0.01" type="sphere" size="0.0005" />
			</body>
			<body name="slider-APL" pos="0.0483392333984375 -0.20248985290527344 -0.26085289306640625">
				<geom type="box" size="0.001 0.001 0.01" rgba="0 0 1 0" />
				<joint type="slide" axis="0 0 1" name="APL_slide" />
				<site name="APL-3" pos="0 0 0.01" type="sphere" size="0.0005" />
			</body>
		</body>
		<camera name="camera0" pos="0.411 0.093 0.213" xyaxes="-0.539 0.842 0.000 -0.231 -0.148 0.962" />
		<camera name="camera0." pos="0.375 0.069 0.146" xyaxes="-0.581 0.814 0.000 -0.114 -0.081 0.990" />
		<camera name="camera1" pos="0.461 0.120 0.252" xyaxes="-0.593 0.805 -0.000 -0.358 -0.264 0.896" />
		<camera name="camera2" pos="0.617 -0.002 0.149" xyaxes="-0.249 0.968 0.000 0.018 0.005 1.000" />
	</worldbody>
	<actuator>
		<motor name="FDP" joint="FDP_slide" gear="10" ctrllimited="true" ctrlrange="-2 0" />
		<motor name="FDS" joint="FDS_slide" gear="10" ctrllimited="true" ctrlrange="-2 0" />
		<motor name="EI" joint="EI_slide" gear="10" ctrllimited="true" ctrlrange="-2 0" />
		<motor name="ED" joint="ED_slide" gear="10" ctrllimited="true" ctrlrange="-2 0" />
		<motor name="EPB" joint="EPB_slide" gear="10" ctrllimited="true" ctrlrange="-2 0" />
		<motor name="APL" joint="APL_slide" gear="10" ctrllimited="true" ctrlrange="-2 0" />
		<motor name="FPL" joint="FPL_slide" gear="10" ctrllimited="true" ctrlrange="-2 0" />
		<motor name="EPL" joint="EPL_slide" gear="30" ctrllimited="true" ctrlrange="-5 0" />
	</actuator>
	<tendon>
		<spatial name="FDP" stiffness="10000.0" damping="200" width="0.0005" rgba="0.9 0.2 0.2 0.3">
			<site site="FDP-1" />
			<geom geom="ZF_PIP1_to_ZF_DIP_wrap" />
			<site site="FDP-2" />
			<geom geom="ZF_PIP2_to_ZF_PIP1_wrap" />
			<site site="FDP-3" />
			<geom geom="ZF_PIP2_to_ZF_PIP1_wrap" />
			<site site="FDP-4" />
			<geom geom="ZF_MCP_to_ZF_PIP2_wrap" />
			<site site="FDP-5" />
			<geom geom="ZF_MCP_to_ZF_PIP2_wrap" />
			<site site="FDP-6" />
			<site site="FDP-7" />
			<site site="FDP-8" />
			<site site="FDP-9" />
		</spatial>
		<spatial name="EPB" stiffness="10000.0" damping="200" width="0.0005" rgba="0.9 0.2 0.2 0.3">
			<site site="EPB-1" />
			<geom geom="DAU_MCP_to_DAU_PIP_wrap" />
			<site site="EPB-2" />
			<geom geom="DAU_CMC_to_DAU_MCP_wrap" />
			<site site="EPB-3" />
			<geom geom="DAU_CMC_to_DAU_MCP_wrap" />
			<site site="EPB-4" />
			<site site="EPB-5" />
		</spatial>
		<spatial name="ED" stiffness="10000.0" damping="200" width="0.0005" rgba="0.9 0.2 0.2 0.3">
			<site site="ED-1" />
			<geom geom="ZF_PIP1_to_ZF_DIP_wrap" />
			<site site="ED-2" />
			<geom geom="ZF_PIP2_to_ZF_PIP1_wrap" />
			<site site="ED-3" />
			<geom geom="ZF_PIP2_to_ZF_PIP1_wrap" />
			<site site="ED-4" />
			<geom geom="ZF_MCP_to_ZF_PIP2_wrap" />
			<site site="ED-5" />
			<geom geom="ZF_MCP_to_ZF_PIP2_wrap" />
			<site site="ED-6" />
			<site site="ED-7" />
			<site site="ED-8" />
			<site site="ED-9" />
		</spatial>
		<spatial name="FDS" stiffness="10000.0" damping="200" width="0.0005" rgba="0.9 0.2 0.2 0.3">
			<site site="FDS-1" />
			<geom geom="ZF_PIP2_to_ZF_PIP1_wrap" />
			<site site="FDS-2" />
			<geom geom="ZF_MCP_to_ZF_PIP2_wrap" />
			<site site="FDS-3" />
			<geom geom="ZF_MCP_to_ZF_PIP2_wrap" />
			<site site="FDS-4" />
			<site site="FDS-5" />
			<site site="FDS-6" />
		</spatial>
		<spatial name="EPL" stiffness="10000.0" damping="200" width="0.0005" rgba="0.9 0.2 0.2 0.3">
			<site site="EPL-1" />
			<geom geom="DAU_PIP_to_DAU_DIP_wrap" />
			<site site="EPL-2" />
			<geom geom="DAU_MCP_to_DAU_PIP_wrap" />
			<site site="EPL-3" />
			<geom geom="DAU_MCP_to_DAU_PIP_wrap" />
			<site site="EPL-4" />
			<site site="EPL-5" />
			<site site="EPL-6" />
		</spatial>
		<spatial name="FPL" stiffness="10000.0" damping="200" width="0.0005" rgba="0.9 0.2 0.2 0.3">
			<site site="FPL-1" />
			<geom geom="DAU_PIP_to_DAU_DIP_wrap" />
			<site site="FPL-2" />
			<geom geom="DAU_MCP_to_DAU_PIP_wrap" />
			<site site="FPL-3" />
			<geom geom="DAU_MCP_to_DAU_PIP_wrap" />
			<site site="FPL-4" />
			<geom geom="DAU_CMC_to_DAU_MCP_wrap" />
			<site site="FPL-5" />
			<site site="FPL-6" />
			<site site="FPL-7" />
		</spatial>
		<spatial name="EI" stiffness="10000.0" damping="200" width="0.0005" rgba="0.9 0.2 0.2 0.3">
			<site site="EI-1" />
			<geom geom="ZF_PIP2_to_ZF_PIP1_wrap" />
			<site site="EI-2" />
			<geom geom="ZF_MCP_to_ZF_PIP2_wrap" />
			<site site="EI-3" />
			<geom geom="ZF_MCP_to_ZF_PIP2_wrap" />
			<site site="EI-4" />
			<site site="EI-5" />
			<site site="EI-6" />
			<site site="EI-7" />
		</spatial>
		<spatial name="APL" stiffness="10000.0" damping="200" width="0.0005" rgba="0.9 0.2 0.2 0.3">
			<site site="APL-1" />
			<geom geom="DAU_CMC_to_DAU_MCP_wrap" />
			<site site="APL-2" />
			<site site="APL-3" />
		</spatial>
	</tendon>
</mujoco>
